Workbook

Sheet Epics
A1: ID | B1: Title | C1: Work Item Type
A2: 251 | B2: Proyecto WAPSA 2024 - 3 | C2: Epic
A3: 252 | B3: Pases a Producción | C3: Epic
A4: 253 | B4: WAPSA BI | C4: Epic
A5: 210 | B5: Proyecto WAPSA 2024 - 2 | C5: Epic
A6: 412 | B6: Proyecto WAPSA 2025 - 1 | C6: Epic
A7: 161 | B7: Soporte | C7: Epic
A8: 175 | B8: Mejoras WAPSA | C8: Epic
A9: 177 | B9: Mejoras Guias Electronicas | C9: Epic
A10: 181 | B10: Proyecto WAPSA 2024 - 1 | C10: Epic
A11: 457 | B11: Proyecto WAPSA 2025 - 2 | C11: Epic

Sheet Hoja1
A1: ID | B1: Title | C1: Work Item Type | D1: Iteration Path | E1: Tipo Caso | F1: Estados | G1: Tags | H1: Start Date | I1: Finish Date | J1: Aplicación | K1: Ticket Chinalco | L1: Ticket SyC | M1: Assigned To | N1: Description | O1: Parent
A2: 226 | B2: Ticket 336 - Wapsa BI - La ejecucion a demanda del reporte de BI de Pesos y Leyes no actualiza data | C2: Ticket | D2: WAPSA\Sprint - Abril -2024 | E2: Repetitivo-en-proceso | F2: Cerrado | H2: 45397 | I2: 45416 | K2: 105868 | L2: 336 | M2: Cristian Pastor Artigas | N2: [Image] El error no se puede replicar en ningun ambiente. 10/04 @Cristian Pastor Artigas Por ende se solicita reunion a Alexander con el DBA 19/04 @Cristian Pastor Artigas Luego de la revision con el DBA se detecta que el script de mover datos de Wapsa a BI esta correcto, se concluye que la falta de data es un problema de logica del script 19/04 @Cristian Pastor Artigas Se soluciona error cambiando el filtro del script para utilizar a la fecha de proceso de MIna y no de Volteo 19/04 @Cristian Pastor Artigas Se preparara formato para enviar ticket 23/04 @Cristian Pastor Artigas Se envia formato para firma de Alejandro 24/04 @Cristian Pastor Artigas Se envio a TICA 01/05 @Cristian Pastor Artigas Alexander envia para formas internas 04/05 @Cristian Pastor Artigas Ticket Ejecutado | O2: WAPSA BI
A3: 241 | B3: Ticket 348 - Valores repetidos en Reporte de Pesos y Leyes del BI | C3: Ticket | D3: WAPSA\Sprint - Mayo -2024 | E3: Nuevo | F3: Cerrado | H3: 45428 | I3: 45440 | J3: Wapsa BI | K3: 107784 | L3: 348 | M3: Cristian Pastor Artigas | N3: Luis Casas inidca que la data del reporte se duplica por lote 15/05 @Cristian Pastor Artigas Se corrige script en BD BI y se prerara script para ejecucion manuald e Wapsa 16/05 @Cristian Pastor Artigas Se prepara formato de Ticket y se envia a AM 16/05 @Cristian Pastor Artigas Enviado a TICA 29/05 @Cristian Pastor Artigas Ejecutado y Cerrado | O3: WAPSA BI
A4: 314 | B4: Ticket 377 - Wapsa BI- Ejecución Manual - Resta copiar guias sin volteo en el reporte de datos de mina | C4: Ticket | D4: WAPSA\Sprint - Octubre - 2024 | E4: Repetitivo-en-proceso | F4: Cerrado | H4: 45540 | I4: 45540 | J4: Wapsa Web | K4: 118265 | L4: 377 | M4: Cristian Pastor Artigas | N4: Luis casas reporta: 1. Falta informacion de Pesos de mina en Reporte de Mina 05/09 @Cristian Pastor Artigas Para firmas | O4: WAPSA BI
A5: 203 | B5: Ticket 322 - Wapsa BI - Reproceso de tabla de Humedades, pesos y leyes Correccion en Wapsa | C5: Ticket | D5: WAPSA\Sprint - Marzo 2024 | F5: Cerrado | H5: 45331 | J5: Wapsa BI | K5: 100715 | L5: 322 | M5: Cristian Pastor Artigas | N5: Ticket 322 - Wapsa BI - Reproceso de tabla de Humedades, pesos y leyes. Script de actualizacion de copia de datos para ejecucion a demanda de humedades, pesos y leyes 20/02 Este ticket depende del 298 se debe enviar el mismo script a Pord de Wapsa 27/02 Se preparan formatos para la firma y enviar ticket 29/02 Enviado a TICA @Cristian Pastor Artigas 01/03 Alexander envia Ticket a Mesa de Servicios @Cristian Pastor Artigas 04/03 Se consulta por el estado del Ticker no se obtiene respuesta @Cristian Pastor Artigas 11/03 Se consulta por el estado del Ticker no se obtiene respuesta @Cristian Pastor Artigas | O5: WAPSA BI
A6: 169 | B6: Ticket 298 - WAPSA BI - Reproceso del dashboard del 01 al 07 enero | C6: Ticket | D6: WAPSA\Sprint - Marzo 2024 | E6: Nuevo | F6: Cerrado | H6: 45315 | J6: WAPSA BI | L6: 298 | M6: Cristian Pastor Artigas | N6: Descripción: Reproceso del dashboard del 01 al 07 enero Sin permisos a la base de datos 30/01 Se tuvo problemas con el usuario 07/02 Se revisa y e total de Guias de enero coinciden con los de Wapsa Se programa reunion con Luis Casas para revisar su BI 08/02 Luego de la reunion se detecta que es un error de rango de fechas en la busqueda de datos en el Wapsa; se corrige y se deja ejecutando para el lote 2301 a la espera de la validacion de LC 16/02 Se tiene script pero el usaurio esta bloqueado para hacer las pruebas 27/02 Se envia script en base de BI y se validara en la siguiente ejecucion automatica. | O6: WAPSA BI
A7: 216 | B7: Ticket 328 - Wapsa BI - Error ejecucion a demanda Humedades, pesos y leyes | C7: Ticket | D7: WAPSA\Sprint - Abril -2024 | E7: Nuevo | F7: Cerrado | H7: 45370 | J7: Wapsa BI | K7: 103122 | L7: 328 | M7: Cristian Pastor Artigas | N7: 19/03 Se envia para firma de Alejandro | O7: WAPSA BI
A8: 235 | B8: Ticket 345: Solicitud de Pase a Producción Wapsa/WapsaUE v2.16 | C8: Ticket | D8: WAPSA\Sprint - Mayo -2024 | E8: Nuevo | F8: Cerrado | G8: [Ver. 2.16] | H8: 45415 | I8: 45432 | J8: Wapsa Web | L8: 345 | M8: Cristian Pastor Artigas | N8: Pase a producción Wapsa V 2.16 Ticket 330 https://dev.azure.com/SycSistemas/WAPSA/_boards/board/t/WAPSA%20Team/Stories/?workitem=218 Ticket 340 https://dev.azure.com/SycSistemas/WAPSA/_workitems/edit/230 Ticket 339 https://dev.azure.com/SycSistemas/WAPSA/_workitems/edit/229 Ticket 331 https://dev.azure.com/SycSistemas/WAPSA/_workitems/edit/219 Ticket 338 https://dev.azure.com/SycSistemas/WAPSA/_workitems/edit/228 03/05 @Cristian Pastor Artigas se crea y se envía documentación para firmas de AM 03/05 @Cristian Pastor Artigas se envia pase a producción 10/05 @Cristian Pastor Artigas Se sube archivo de Manual de Usuario Actualizado 15/06 @Cristian Pastor Artigas Se suben sustentos Casos de prueba, y Alexander envia scripts a DBA para su ejecucion del pase final, a la espera de definir dia | O8: Pases a Producción
A9: 245 | B9: Ticket 351: Solicitud de Pase a Producción Wapsa/WapsaUE v2.16.1 | C9: Ticket | D9: WAPSA\Sprint - Mayo -2024 | E9: Nuevo | F9: Cerrado | G9: [2.16.1] | H9: 45415 | I9: 45441 | J9: Wapsa Web | L9: 351 | M9: Cristian Pastor Artigas | N9: Pase a producción Wapsa V 2.16.1 Ticket 350 https://dev.azure.com/SycSistemas/WAPSA/_boards/board/t/WAPSA%20Team/Stories/?workitem=243 Ticket 352 https://dev.azure.com/SycSistemas/WAPSA/_boards/board/t/WAPSA%20Team/Stories/?workitem=244 22/05 @Cristian Pastor Artigas se crea y se envía documentación para firmas de AM 23/05 @Cristian Pastor Artigas Enviado a TICA 27/05 @Cristian Pastor Artigas WM adjunta evidencias de pruebas. Se esta a la espera de definir por parte de TICA el dia y hora de hacer los cambios en producción 29/05 @Cristian Pastor Artigas Cerrado | O9: Pases a Producción
A10: 285 | B10: Ticket 366: Solicitud de Pase a Producción Wapsa/WapsaUE v2.17 | C10: Ticket | D10: WAPSA\Sprint - Septiembre - 2024 | E10: Nuevo | F10: Cerrado | G10: [Ver. 2.17] | H10: 45488 | J10: Wapsa Web | K10: 102342 | L10: 366 | M10: Cristian Pastor Artigas | N10: Pase a producción Wapsa V 2.17 Ticket 307 - Proyecto WAPSA 2024 - 2 - Mejoras en el cuadre en Wapsa https://dev.azure.com/SycSistemas/WAPSA/_boards/board/t/WAPSA%20Team/Stories/?workitem=186 Ticket 353 - Mina - Lista de Despachos-Se generó un registro duplicado al preasignar vagón por intervención del usuario https://dev.azure.com/SycSistemas/WAPSA/_boards/board/t/WAPSA%20Team/Stories/?workitem=246 Ticket 346 - Guias Electronicas - Proyecto Mejoras WAPSA - 2 - Nuevo Modulo "Emisión de Guias Impala 01" https://dev.azure.com/SycSistemas/WAPSA/_boards/board/t/WAPSA%20Team/Stories/?workitem=236 Ticket 364 - Callao - Lista de Despachos - El filtro por IE's en estado abierto no muestra las que tiene peso = 0 https://dev.azure.com/SycSistemas/WAPSA/_boards/board/t/WAPSA%20Team/Stories/?workitem=282 Ticket 347 - Guias Electronicas - Proyecto Mejoras WAPSA - 2 - GRE Impresión Guías - Hipervinculos https://dev.azure.com/SycSistemas/WAPSA/_boards/board/t/WAPSA%20Team/Stories/?workitem=237 15/07 @Cristian Pastor Artigas Creando documentos 16/07 @Cristian Pastor Artigas Se envia para firmas de AM 18/07 @Cristian Pastor Artigas Enviado a TICA | O10: Pases a Producción
A11: 316 | B11: Ticket 379 - Wapsa - Solicitud de Pase a Producción Wapsa/WapsaUE v2.18 | C11: Ticket | D11: WAPSA\Sprint - Octubre - 2024 | E11: Nuevo | F11: Cerrado | G11: [Ver. 2.18] | H11: 45545 | J11: Wapsa Web | K11: 120145 | L11: 379 | M11: Cristian Pastor Artigas | N11: Pase a producción Wapsa V 2.18 Ticket 302 - Guias Electronicas - Proyecto Mejoras WAPSA - 2 - Entregas Directas - Cambiar como se registra el destinatario, que no sea desde el maestro. https://dev.azure.com/SycSistemas/WAPSA/_boards/board/t/WAPSA%20Team/Stories/?workitem=178 Ticket 372 - Modulo Mina - Pesaje Manual - Mejora-Ver vagones observados https://dev.azure.com/SycSistemas/WAPSA/_boards/board/t/WAPSA%20Team/Stories/?workitem=308 Ticket 373 - Modulo Mina - Pesaje - Mejora correos supervisores https://dev.azure.com/SycSistemas/WAPSA/_boards/board/t/WAPSA%20Team/Stories/?workitem=309 Ticket 375 - Modulo Pesaje - Vagones observados - no filtra por los estados https://dev.azure.com/SycSistemas/WAPSA/_boards/board/t/WAPSA%20Team/Stories/?workitem=311 Ticket 376 - Modulo Pesaje - Registro cambio check auto/manual peso tara https://dev.azure.com/SycSistemas/WAPSA/_boards/board/t/WAPSA%20Team/Stories/?workitem=312 Ticket 383 - Callao - Volteo - Link para descargar PDF en Guias Electronicas | O11: Pases a Producción
A12: 290 | B12: Ticket 367: Solicitud de Pase a Producción Servicio Movil Wapsa v1.1 | C12: Ticket | D12: WAPSA\Sprint - Agosto - 2024 | E12: Nuevo | F12: En Produccion | G12: [Ver. 1.1] | H12: 45491 | J12: Wapsa Web | L12: 367 | M12: Cristian Pastor Artigas | N12: Pase a producción Servicio Movil Wapsa v1.1 Ticket 346 - Proyecto WAPSA 2024 - 2 - Mejoras en el Inspeccion WAPSA movil https://dev.azure.com/SycSistemas/WAPSA/_boards/board/t/WAPSA%20Team/Stories/?workitem=238 Ticket 308 - Proyecto WAPSA 2024 - 2 - Mejoras en el cuadre en Wapsa Movil https://dev.azure.com/SycSistemas/WAPSA/_boards/board/t/WAPSA%20Team/Stories/?workitem=187 18/07 @Cristian Pastor Artigas Se envia para firma de AM | O12: Pases a Producción
A13: 213 | B13: Ticket 326 Pase a Produccion Wapsa/WapsaUE v2.15 | C13: Ticket | D13: WAPSA\Sprint - Marzo 2024 | F13: Cerrado | G13: [Ver. 2.15] | H13: 45365 | J13: Wapsa | K13: 102342 | L13: 326 | M13: Cristian Pastor Artigas | N13: Pase a produccion Version 2.15 Ticket 303 - Proyecto WAPSA 2024 - 1 - Mejoras Embarque a Granel"Extraporturario" Lista despacho. Ticket 305 - Proyecto WAPSA 2024 - 1 - Mejoras Reporte TMH, TMS,HUMEDAD Lista despacho. · Ticket 326 - El registro de Pesaje de Mina Muestra ventana dediferencias de peso tara al momento de preasignar. Ticket 313 - Proyecto WAPSA 2024 - 1 - Aprobación Supervisor por ladiferencia de peso tara en mina. Ticket 327 - Corrección error al hacer la aprobación de Pesaje ManualMódulo. Ticket 314 - Proyecto WAPSA 2024 - 1 - Alerta Lista Despacho. 14/03 Se envian documentos para firma de AM @Cristian Pastor Artigas 18/03 AM responde documentos firmados 18/03 Se envia Ticket a TICA para iniciar pase @Cristian Pastor Artigas 20/03 TICA pasa a testing 20/03 Wally revisa y envia correcciones sobre los tickets #192 y #182 20/03 TICA asigna ticket MCP #102342 | O13: Pases a Producción
A14: 207 | B14: Ticket 324 - Pase a Produccion Wapsa Servicio Ver. 2.4 | C14: Ticket | D14: WAPSA\Sprint - Febrero 2024 | F14: Cerrado | G14: [Ver.2.4] | H14: 45338 | I14: 45343 | L14: 324 | M14: Cristian Pastor Artigas | N14: Pase a Produccion Wapsa Servicio Ver. 2.4 15/02: Se moven cambio para preparar version PR 171: Correccion servicio ver 2.4 16/02: @Cristian Pastor Artigas Se envian formatos a firma de AM 20/02 Aprobo Alexander el pase 22/02 TICA realizo el pase a Produccion son documentacion de casos de pruebas @Cristian Pastor Artigas | O14: Pases a Producción
A15: 200 | B15: Ticket 318 - Pase a Producción Wapsa Ver 2.14 | C15: Ticket | D15: WAPSA\Sprint - Febrero 2024 | F15: Cerrado | G15: [Ver.2.14] | H15: 45328 | I15: 45355 | J15: Wapsa | K15: #100230 | L15: 319 | M15: Cristian Pastor Artigas | N15: Pase a produción Wapsa UE y Wapsa * Ticket 319 - Modulo Mina - Mover opciones de aprobación por guía a la pestaña de observados * Ticket 295 - Modulo Mina Pesaje - Nuevo filtro en la vista de vagones observados * Ticket 293 - Modulo mina - los adjuntos para Diferencia de peso tara se estan guardando mal * Ticket 294 - Modulo Mina - Vista de Vagones observados no filtra ni exporta correctamente * Ticket 316 - Modulo Mina - No deja adjuntar las evidencias para duplicidad de precintos * Ticket 301 - Modulo Callao - DIFERENCIA DE PESOS BRUTOS CALLAO * Ticket 296 - Modulo Callao Lista Despacho - Corregir "ITEM" cuando das click en ver "Detalle" por una IE 5/02: Recibidos documentos firmado por Alejandro 6/02: Documentos y mail enviados a TICA 9/02: Disponible en Testing para las pruebas 12/02: Pruebas con Wally: -Volteo: Solo se tomará en cuenta para obervar el vagon si es que los pesos brutos si es que la diferencia de pesos de Callao y Mina es inferior al factor. -Inspeccion callao: Correccion de error al agregar sustento al editar el vagon. PR 169: Cambio de Factor y correccion adjuntar editar vagon inspeccion 13/02 Revision con WM se aprueban todas las correciones del CP Se solicita corregir un texto en la evidencias del pesaje de mina 14/02 Correccion texto en la evidencias del pesaje de mina PR 170: Correcciones para texto en adjuntos y corregir error de adjuntado en diferencia de pesos mina 16/02 Se envian a Wally las evidencias del pase. Quedamos a la espera de una ultima prueba al pesaje por parte de Wally para cerrar el pase 19/02 Se solicita a Julio que envie el link para que Wally suba las evidencias. Se queda la espera de fecha del pase 23//02 Alexander asigna el pase a Produccion a Saul para que inidque el dia y hora. 26/02 El pase es reasignado a Julio, en un mail indica que esta por firmas de documentos. 27/02 @Cristian Pastor Artigas Se solicita actualizacion de estado del pase 01/03 Julio realiza pase pero solo de Wapsa falta WapsaEU @Cristian Pastor Artigas | O15: Pases a Producción
A16: 248 | B16: Ticket 355 Proyecto - Agregar grupos de Ensayo en Wapsa | C16: Ticket | D16: WAPSA\Sprint - Enero - 2025 | E16: Nuevo | F16: En Desarrollo | J16: Wapsa Web | L16: 355 | N16: Luis Casas solicita: En la transmision de leyes de Cotecna e importacion: - Habilitar 4 columnas de información en el reporte de H2OyLey Callao de Wapsa; grupos (G1,G2,G3,G4) para recibir la data de Cotecna - Generar el maestro: "Grupos de análisis" para seleccionar a qué grupo pertenece cada analito. - Actualizar el reporte en Excel de H2OyLey Callao incluyendo los Grupos. - Habilitar las 4 columnas en el dashboard (HumedadesyLeyes) 28/05 @Cristian Pastor Artigas Se adjunta documento resultante de la reunion | O16: Proyecto WAPSA 2024 - 3
A17: 194 | B17: Ticket 315 - Proyecto WAPSA 2024 - 1 - Mejoras Logs | C17: Ticket | D17: WAPSA | E17: Nuevo | F17: Nuevo | H17: 45540 | J17: WAPSA web | L17: 315 | M17: Cristian Pastor Artigas | N17: Modulo Log 1.1 Listado Log * Mejorar el performance del modulo de logs es demasiado lento * Desarrollar funcioanlidad para guardar los datos del request cuadno se realizan ejemplo si se guardan leyes que valores estan siendo enviados al WAPSA para grabarse. * Modificar scripts para soportar esta nueva columna que obtendrá los datos de datos enviados * Crear nuevas tablas para manejar las llaves y adjuntos * Modificar la UI para poder ver esta nueva columna * Realizar pruebas | O17: Proyecto WAPSA 2024 - 3
A18: 223 | B18: Ticket 333 - Proyecto Wapsa - Rountrip con GPS | C18: Ticket | D18: WAPSA\Sprint - Enero - 2025 | E18: Nuevo | F18: Nuevo | H18: 45392 | J18: Wapsa Web | K18: 333 | N18: 10/04 @Cristian Pastor Artigas Reunion con el proveedor CLS Peru en la cual se concretaron los siguientes puntos: -En la aplicacion de CLS que le permite a MIna monitorear los vagones via GPS se registrar el Nro de Guia de Remision en el campo conductor, de momento manualmente lo hara el equipo de Edwin Rios MCP. -El equipo de Edwin registrara la guias desde el Jueves 11/04 hasta el dia lunes para que luego de eso SyC Sistemas podra 15/04 consultar utilizando el API. -EL dia 15/04 SyC probara haciendo consultas utilizando el API para devolver los datos filtrando por el campo conductor-Guia de remision, -La proxima reunion sera el dia 18 o 19/04 -Se concretara una reunion con Wally a posterior para ver internamnete en Wapsa cuales seran las mejoras una vez podamos consultar la informacion correctamnete desde el API -CLS indico cual es la documentacion que se debe consultar. https://sdk.wialon.com/wiki/en/sidebar/remoteapi/apiref/report/cleanup_result @Cristian Pastor Artigas Video de la reunion en los adjuntos del Ticket 15/04 Edwin Rios inidca que ya se esta cargando los Numeros de Guias desde Mina 16/04 @Cristian Pastor Artigas Se envia consulta a la Empresa del GPS para consultar sobre como obtener los ID's para obtener lueo los reportes 23/04 @Cristian Pastor Artigas CLS responde mail enviando las credenciales de acceso 29/04 @Cristian Pastor Artigas Se envia consulta a CLS porque no se puede obtener la informacion de los puntos del GPS , se solicita reunion | O18: Proyecto WAPSA 2024 - 3
A19: 190 | B19: Ticket 311 - Proyecto WAPSA 2024 - 1 - Envío de información a Impala a través de un servicio | C19: Ticket | D19: WAPSA | E19: Nuevo | F19: Nuevo | J19: WAPSA servicio | L19: 311 | N19: 1.Agregar nuevo controlador para enviar informacion a IMPALA Envio de datos * Crear scripts para obtener los datos * Crear logica en el controlador para enviar los mensajes Validaciones * Crear validaciones para los ejes * Modificar el WAPSA para mostrar las validaciones * Crear logica para identificar cuando se reasigno la ruma para actualizar los datos de impala * Realizar pruebas 2.Ejes de Ruma Liberacion de ejes * Crear logica apra librerar ejes * Modificar el WAPSA para usar esta validación * Realizar pruebas 3.Reportes * Crear reporte de ejes de ruma donde se mostraran los eje en uso y los que esten libres para asignación | O19: Proyecto WAPSA 2024 - 3
A20: 183 | B20: Ticket 304 - Proyecto WAPSA 2024 - 1 - Modificar Proceso Lista despacho | C20: Ticket | D20: WAPSA | E20: Nuevo | F20: Nuevo | J20: WAPSA web | L20: 305 | N20: Descripción: 1.1 Pesos Lista Despacho * Modicar codigo en el momento que se modifiquen pesos se deben eliminar las leyes y humedades existentes. * Modificar UI para consumir nuevo proceso * Realizar pruebas 1.2 Humedades Lista Despacho * Modicar codigo en el momento que se modifiquen pesos se deben eliminar las leyes. * Modificar UI para consumir nuevo proceso * Realizar pruebas Solución: | O20: Proyecto WAPSA 2024 - 3
A21: 191 | B21: Ticket 312 - Proyecto WAPSA 2024 - 1 - Ajuste final y Repeso total | C21: Ticket | D21: WAPSA | E21: Nuevo | F21: Nuevo | J21: WAPSA web | L21: 312 | N21: Ajuste final y Repeso total 1.1 Ajuste final * Modificar lógica para creación de ajuste para validar lo siguiente: al realizar el ajuste la fecha y hora debe ser mayor al último movimiento (ingreso, salida, junta). * Modificar la UI para mostrar el mensaje y consumir la validación * Realizar pruebas 1.2 REPESO TOTAL * Modificar lógica para creación de ajuste para validar lo siguiente: al realizar el ajuste la fecha y hora debe ser mayor al último movimiento (ingreso, salida, junta). * Modificar la UI para mostrar el mensaje y consumir la validación * Realizar pruebas 1.3 Validaciones adicionales * Crear validacion para poder crear un bloqueo de pesos en tmh si se genera un "Ajuste en TMH" * Crear validacion para poder crear un bloqueo de pesos en tms si se genera un "Ajuste en TMS" * Modificar cada punto de creación de pesos (TMH,TMS) para consumir la validación * Modifcar la UI para consumir estas validaciones * Realizar pruebas | O21: Proyecto WAPSA 2024 - 3
A22: 189 | B22: Ticket 310 - Proyecto WAPSA 2024 - 1 - Arribo a Mina y a Callao con GPS | C22: Ticket | D22: WAPSA | E22: Nuevo | F22: Nuevo | J22: WAPSA web | L22: 310 | N22: Crear una API 1.1 Crear proceso automatico para leer datos del GPS * Creacion de scripts * Desarrollo del codigo con logica 1.2 Modificar el wapsa * Modificar el WAPSA para soportar una lectura del gps o manual * Realizar pruebas | O22: Proyecto WAPSA 2024 - 3
A23: 185 | B23: Ticket 306 - Proyecto WAPSA 2024 - 1 - Mantenimiento Equipos-Pesajes | C23: Ticket | D23: WAPSA | E23: Nuevo | F23: Nuevo | J23: WAPSA web | L23: 306 | N23: Mantenimiento de tablas 1.1 Registro de Equipos * Registro de los equipos * Configurar cuenta de correo 1.2 Mantenimiento de tablas * Tipos de mantenimiento * Tipos de averias * Empresas * Ubicación Registro de la programación 2.1 Registro de programación * Registro de programación * Registro de evidencias * Envío de la notificación 2.2 Registro de mantenimiento correctivo * Registro del evento * Registro de las evidencias Reportes * Reporte de programación * Reporte de Mantenimiento Correctivo | O23: Proyecto WAPSA 2024 - 3
A24: 218 | B24: Ticket 330 - Mejora WAPSA Lista Despacho Diferencias Peso - Embarque Granel | C24: Ticket | D24: WAPSA\Sprint - Mayo -2024 | E24: Nuevo | F24: Cerrado | G24: [Ver. 2.16] | H24: 45383 | J24: WAPSA web | L24: 330 | M24: Cristian Pastor Artigas | N24: Descripción: Se requiere que el WAPSA en la lista despacho se tenga un nuevo filtro para saber si estan observador por el nuevo factor para los casos de "Embarque a Granel" y adicional se requeire cambio de los titulos. Diferencia Balanzas (Almacén 2 - Almacen) Si / No Diferencia Balanzas (Puerto - Almacen) Si / No Ahora: Extraportuario Nuevo: Extraportuario / Balanza 2 Ahora: Almacen Nuevo: Almacen / Balanza 1 Solicitado por Wally Moscoso 20/03 Solución: @Cristian Pastor Artigas Se crea nuevas columnas en el listado y excel con la logica para mostrar el valor de Si/No, pendiente el filtro @Cristian Pastor Artigas Se crea filtro 02/04 @Cristian Pastor Artigas Se envia a 06/04 Wally para revision inidca lo siguiente: -Ajustar nombre de columnas -Agregar una configuracion para indicar el codigo del la IE a partir de la cual debe iniciar a funcionar el filtro de diferencias @Cristian Pastor Artigas Se crea configuracion para que el usuario pueda indicar la IE, se ajustan nombres de campos | O24: Proyecto WAPSA 2024 - 2
A25: 240 | B25: Tickets 347 - Actualizar Manual Usuario de Wapsa | C25: Ticket | D25: WAPSA\Sprint - Mayo -2024 | E25: Nuevo | F25: Cerrado | H25: 45419 | I25: 45422 | J25: Wapsa Web | L25: 347 | M25: Cristian Pastor Artigas | N25: Por solicitud de TICA(Alexander) en reunion del 07/05 se solicita actualizar el Manual de Usuario de Wapsa 07/05 @Cristian Pastor Artigas Se actualiza manual y se sube al servidor de SyC | O25: Proyecto WAPSA 2024 - 2
A26: 250 | B26: Ticket 356 - Servicios Web Callao | C26: Ticket | D26: WAPSA\Sprint - Enero - 2025 | E26: Nuevo | F26: Nuevo | G26: [Ver. 1.3] | H26: 45447 | J26: WAPSA web | L26: 356 | M26: Cristian Pastor Artigas | N26: Descripción: [Image] Solución: 05/06 @Cristian Pastor Artigas Se modifica servicio primeros cambios Volteo Callao. 10/06 @Cristian Pastor Artigas Se crean lo cambios para que marque con diferencias cuando el peso de Callao excede el de Mina segun factor. 14/06 @Cristian Pastor Artigas Se revisa y se hacen los cambios para el servicio de recepcion de pesos para: Contenerdor Directo, Extraportuario, Traslado Entre establacimientos y Granel Resta revisar Humedades 19/06 @Cristian Pastor Artigas Esta creado un servicio para los pesos pero puede cambiarse a que se reciban por la GRE, falta definir si Impala enviara la IE por el servicio de GRE. Reunion 20/06 20/06 @Cristian Pastor Artigas En reunion: Se envia informacion a impala sobre los servicios y a lo interno van a definir los tiempos que tomaría el desarrollo. Impala queda en enviarnos el TAG dentro del cual no esta enviando la IE d eImpala al momento de crear la GRE. A la espera de la informacion de Impala para hacer los cambio en servicio de la GRE para grabar los pesos. | O26: Proyecto WAPSA 2024 - 2
A27: 178 | B27: Ticket 302 - Guias Electronicas - Proyecto Mejoras WAPSA - 2 - Entregas Directas - Cambiar como se registra el destinatario, que no sea desde el maestro. (mejora posterior | C27: Ticket | D27: WAPSA\Sprint - Octubre - 2024 | E27: Nuevo | F27: Cerrado | G27: [Ver. 2.18] | H27: 45446 | J27: WAPSA web | L27: 302 | M27: Cristian Pastor Artigas | N27: los Descripción: o Para entregas directas: Cambiar como se registra el destinatario, que no sea desde el maetro. (mejora posterior) [Image] Solución: 03/06 @Cristian Pastor Artigas -Creado Lote automatico 28/06 @Cristian Pastor Artigas Punto 1,2,3,4 Terminado 02/07 @Cristian Pastor Artigas En proceso Punto 5, Se revisó requerimiento con Michael. esta al 100% 24/07 @Cristian Pastor Artigas Se implementa cambio en el servicio externo para que grabe correctamente el tipo de Venta de las GRE emitidas por Impala | O27: Proyecto WAPSA 2024 - 2
A28: 186 | B28: Ticket 307 - Proyecto WAPSA 2024 - 2 - Mejoras en el cuadre en Wapsa | C28: Ticket | D28: WAPSA\Sprint - Septiembre - 2024 | E28: Nuevo | F28: Cerrado | G28: [Ver. 2.17] | H28: 45418 | I28: 45425 | J28: WAPSA Web | L28: 307 | M28: Cristian Pastor Artigas | N28: 1.1 Callao-Cuadre scripts * Modificación de scripts 1.2 Callao-Cuadre interfaz * Modificar interfaz para colocar la columna(Ruma) nuevas en la grilla * Modificar "input select" para filtrar solo vagones en arribo y agregar al vagon la ruma * Pruebas Logs * Modificar script del log para mostrar los estados correctamente y describir los datos de los errores * Pruebas en el modulo 06/05 @Cristian Pastor Artigas Se realizan los cambios 10/05 @Cristian Pastor Artigas Se realizan cambios en la App movil para igualar con el Wapsa Web | O28: Proyecto WAPSA 2024 - 2
A29: 239 | B29: Ticket 238: Ticket 347 - Actualizar documentacion de Wapsa | C29: Ticket | D29: WAPSA\Sprint - Mayo -2024 | E29: Nuevo | F29: Cerrado | H29: 45419 | I29: 45422 | J29: Wapsa Web | L29: 347 | M29: Cristian Pastor Artigas | N29: Actualizar documentacion de Wapsa (Manual de Usuario) @Cristian Pastor Artigas Se actualiza el manual y se adjunta en el ticket https://dev.azure.com/SycSistemas/WAPSA/_boards/board/t/WAPSA%20Team/Stories/?workitem=235 | O29: Proyecto WAPSA 2024 - 2
A30: 238 | B30: Ticket 346 - Proyecto WAPSA 2024 - 2 - Mejoras en el Inspeccion WAPSA movil | C30: Ticket | D30: WAPSA\Sprint - Agosto - 2024 | E30: Nuevo | F30: En Produccion | G30: [Ver. 1.1] | H30: 45421 | I30: 45422 | J30: Wapsa Movil | L30: 346 | M30: Cristian Pastor Artigas | N30: La inspeccion en la app movil no funciona solo permite registrar inspecciones sin fotos. 10/05 @Cristian Pastor Artigas Se corrige: -Registro de Convoy -Listar vagones para inspeccion' -Registro de Vagones con sustentos -Se iguala el flujo de registro de vagones observados para que genere la aprobacion con la foto que se toma con la camara, con el flujo del Wapsa Web -Listado de Vagones por convoy ! | O30: Proyecto WAPSA 2024 - 2
A31: 237 | B31: Ticket 347 - Guias Electronicas - Proyecto Mejoras WAPSA - 2 - GRE Impresión Guías - Hipervinculos | C31: Ticket | D31: WAPSA\Sprint - Agosto - 2024 | E31: Nuevo | F31: En Testing | G31: [Ver. 2.17] | H31: 45440 | I31: 45483 | J31: WAPSA web | L31: 347 | M31: Frank Macavilca | N31: Descripción: [Image] [Image] Solución: | O31: Proyecto WAPSA 2024 - 2
A32: 236 | B32: Ticket 346 - Guias Electronicas - Proyecto Mejoras WAPSA - 2 - Nuevo Modulo "Emisión de Guias Impala 01" | C32: Ticket | D32: WAPSA\Sprint - Septiembre - 2024 | E32: Nuevo | F32: Cerrado | G32: [Ver. 2.17] | H32: 45427 | J32: WAPSA web | L32: 346 | M32: Cristian Pastor Artigas | N32: Descripción: [Image] Solución: 20/05 @Cristian Pastor Artigas Se realiza creacion de modulo agregando las vistas y controlador, de momento muestra la misma informacion del que modulo de ED 28/05 @Cristian Pastor Artigas Se finaliza desarrollo y se enviará a testing para revision con Michael 29/05 @Cristian Pastor Artigas Se envia a testing para pruebas. A la espera que TICA actualice el ambien para verlo con MC. 11/06 @Cristian Pastor Artigas Se cambia a estado en desarrollo. Se revisa con Wally y se solicita cambiar: Origen por: ALMACÉN DE MCP (MARIÁTEGUI) Destino: IMPALA 01 Guías de Venta por solo Guía Se debe enviar formato de PDF de GUIA MCP (Antiguo) para que MC proponga los cambios al formato. Se debe enviar formato el TXT de la GRE para que MC lo valide con NeoGrid y envie sus comentarios. 11/06 @Cristian Pastor Artigas Se realizan los cambios. PR 189: Principal PR Modulo de Impresion de Guias Impala 01 Ticket 346 y Parte 1 Ticket 356 Se envian formatos para validacion de MC Se deja Ticket en Desarollo hasta obtener respuesta de MC 09/07 @Cristian Pastor Artigas Se envia a testing cambis en TXT y PDF y para validacion final a MC. | O32: Proyecto WAPSA 2024 - 2
A33: 187 | B33: Ticket 308 - Proyecto WAPSA 2024 - 2 - Mejoras en el cuadre en Wapsa Movil | C33: Ticket | D33: WAPSA\Sprint - Agosto - 2024 | E33: Nuevo | F33: En Produccion | G33: [Ver. 1.3] | H33: 45421 | I33: 45425 | J33: WAPSA movil | L33: 309 | M33: Cristian Pastor Artigas | N33: 2.1 Callao-Cuadre interfaz * Modificar aplicación para agregar el cambio * Modificar "input select" para filtrar solo vagones en arribo y agregar al vagon la ruma * Realizar pruebas @Cristian Pastor Artigas Se implementan los cambios | O33: Proyecto WAPSA 2024 - 2
A34: 193 | B34: Ticket 314 - Proyecto WAPSA 2024 - 1 - Alerta Lista Despacho | C34: Ticket | D34: WAPSA\Sprint - Abril -2024 | E34: Nuevo | F34: Cerrado | G34: [Ver. 2.15] | H34: 45356 | I34: 45376 | J34: WAPSA web | L34: 314 | M34: Frank Macavilca | N34: Modulo Lista Despacho 1.1 Nuevo proceso * crear un factor nuevo para usarlo en el Peso de la IE en el WAPSA * Modificar la UI para poder crear el nuevo flujo de aprobación para la IE que tiene valor en peso 0 pasado 7 días(configurable) - luego enviar un correo diario 7 am * Desarrollar codigo para las notifiaciones por correo o WAPSA * Realizar pruebas | O34: Proyecto WAPSA 2024 - 1
A35: 192 | B35: Ticket 313 - Proyecto WAPSA 2024 - 1 - Aprobación Supervisor por la diferencia de peso tara en mina | C35: Ticket | D35: WAPSA\Sprint - Marzo 2024 | E35: Nuevo | F35: Cerrado | G35: [Ver. 2.15] | H35: 45356 | J35: WAPSA web | L35: 313 | M35: Cristian Pastor Artigas | N35: Modulo Mina - Pesaje 1.1 Proceso Peso Tara * crear script para nueva columna para aprobación para un segundo supervisor * Modificar script de Listar,Insert, Update para soportar nueva columna * Modificar codigo para utilizar el nuevo campo * Modificar la UI para que pueda aprobar el segundo supervisor * Crear nuevo proceso para enviar correo para el segundo supervisor * Realizar pruebas 11/03 Se finaliza la implementacion quedando en cola para pruebas | O35: Proyecto WAPSA 2024 - 1
A36: 184 | B36: Ticket 305 - Proyecto WAPSA 2024 - 1 - Mejoras Reporte TMH,TMS, HUMEDAD Lista despacho | C36: Ticket | D36: WAPSA\Sprint - Marzo 2024 | E36: Nuevo | F36: Cerrado | G36: [Ver. 2.15] | J36: WAPSA web | L36: 306 | M36: Frank Macavilca | N36: Descripción: 1.1 Store Procedures * Modificacion de scripts en la lógica 1.2 Interfaz WAPSA * Modificación de javascript para mostrar los datos correctos en la vista de "Leyes" por IE * Realizar pruebas Solución: | O36: Proyecto WAPSA 2024 - 1
A37: 182 | B37: Ticket 303 - Proyecto WAPSA 2024 - 1 - Mejoras Embarque a Granel "Extraporturario" Lista despacho | C37: Ticket | D37: WAPSA\Sprint - Marzo 2024 | E37: Nuevo | F37: Cerrado | G37: [Ver. 2.15] | J37: WAPSA web | L37: 304 | M37: Frank Macavilca | N37: Descripción: 1.1 Store Procedures * Script para crear nueva columna * Modificar script de Listar,Insert, Update para soportar nueva columna 1.2 Interfaz WAPSA * Modificación de javascript para mostrar los datos * Modificar el código para soportar esta nueva columna agregada al modelo de datos Realizar pruebas 1.3 Notificación * crear un factor nuevo para usarlo en el Peso de la IE en el WAPSA * Modificar la UI para poder crear el nuevo flujo de aprobación para la IE en la diferencia de pesos es mayor que el factor definido * Crear codigo para crear los flujos de aprobación * Crear nuevas tablas para manejar las llaves y adjuntos * Desarrollar código para las notificaciones por correo o WAPSA * Realizar pruebas Ver Adjunto de Referencia | O37: Proyecto WAPSA 2024 - 1
A38: 179 | B38: Ticket 303- Guias Electronicas - Contenedores/Traslados Externos - Realizar mejora en el peso de las guías de Impala, dado que el peso está en kg | C38: Ticket | D38: WAPSA\Sprint - Enero 2024 | E38: Nuevo | F38: Cerrado | G38: [Ver.2.13] | H38: 45315 | I38: 45315 | J38: WAPSA web | L38: 303 | M38: Frank Macavilca | N38: Descripción: Guias Electronicas - Contenedores/Traslados Externos - Realizar mejora en el peso de las guías de Impala, dado que el peso está en kg Solución: | O38: Mejoras Guias Electronicas
A39: 166 | B39: Ticket 295 - Modulo Mina Pesaje - Nuevo filtro en la vista de vagones observados | C39: Ticket | D39: WAPSA\Sprint - Febrero 2024 | E39: Nuevo | F39: Cerrado | G39: [Ver.2.14] | H39: 45315 | J39: WAPSA web | L39: 295 | M39: Cristian Pastor Artigas | N39: Descripción: Mina/despacho, vagones observado: filtros de la vista de vagones observados, debe haber dos estatus (aprobados, pendientes *) *pendientes: hasta que tenga algo pendiente de aprobar Solución: Se corrige filtro por estado, se agrega filtro para ver si hay aprobaciones pendientes: 1-Pend. Aut. Tara 2-Pend. Aut. Bruto 3-Pend. Aut. Uso Peso. Man. Tara 4-Pend. Aut. Uso Peso. Man. Bruto 5-Pend. Aut. Uso Precintos Duplicados 6-Todos | O39: Mejoras WAPSA
A40: 222 | B40: Ticket 332 - Callao-Lista de Despachos-Error en plantilla correo de JOB Factor Pesos | C40: Ticket | D40: WAPSA\Sprint - Abril -2024 | E40: Nuevo | F40: Cerrado | H40: 45389 | J40: Wapsa Web | K40: 103860 | L40: 332 | M40: Cristian Pastor Artigas | N40: EL JOB en produccion envia el mail periodicamente pero con error al mostrar la plantilla [Image] 08/04: @Frank Macavilca Corrige script para enviarlo como Ticket 08/04 @Cristian Pastor Artigas Se envia a Alejandro para firma 09/04 @Cristian Pastor Artigas Enviado a TICA | O40: Soporte
...

Sheet Hoja2
A1: ID | B1: Work Item Type | C1: Title | D1: Iteration Path | E1: Estados | F1: Tags | G1: Start Date | H1: Finish Date | I1: Finish Date Chinalco | J1: Aplicación | K1: Ticket Chinalco | L1: Ticket SyC | M1: Assigned To | N1: Description | O1: Tipo Caso | P1: Tipo Evento | Q1: Tipo Estabilización | R1: Parent | S1: Epic
A2: 191 | B2: Ticket | C2: Ticket 312 - Proyecto WAPSA 2024 - 1 - Ajuste final y Repeso total | D2: WAPSA\Sprint - Septiembre- 2025 | E2: Nuevo | G2: 31/8/2025 7:00:00 p. m. | H2: 14/9/2025 7:00:00 p. m. | I2: 28/12/2025 7:00:00 p. m. | J2: WAPSA web | L2: 312 | N2: Ajuste final y Repeso total 1.1 Ajuste final Modificar lógica para creación de ajuste para validar lo siguiente: al realizar el ajuste la fecha y hora debe ser mayor al último movimiento (ingreso, salida, junta). Modificar la UI para mostrar el mensaje y consumir la validación Realizar pruebas 1.2 REPESO TOTAL Modificar lógica para creación de ajuste para validar lo siguiente: al realizar el ajuste la fecha y hora debe ser mayor al último movimiento (ingreso, salida, junta). Modificar la UI para mostrar el mensaje y consumir la validación Realizar pruebas 1.3 Validaciones adicionales Crear validacion para poder crear un bloqueo de pesos en tmh si se genera un "Ajuste en TMH" Crear validacion para poder crear un bloqueo de pesos en tms si se genera un "Ajuste en TMS" Modificar cada punto de creación de pesos (TMH,TMS) para consumir la validación Modifcar la UI para consumir estas validaciones Realizar pruebas | O2: Nuevo | P2: Requerimiento Nuevo-Area Comercial | Q2: No implica estabilización | R2: 251 | S2: =VLOOKUP(R2,Epics!A:B,2,FALSE) -> Proyecto WAPSA 2024 - 3
A3: 194 | B3: Ticket | C3: Ticket 315 - Wapsa - Proyecto WAPSA 2024 - 1 - Mejoras Logs | D3: WAPSA\Sprint - Octubre - 2025 | E3: Cerrado | F3: [Ver 2.25] | G3: 4/9/2024 7:00:00 p. m. | H3: 7/10/2025 1:54:00 p. m. | I3: 7/10/2025 1:54:00 p. m. | J3: WAPSA web | L3: 315 | M3: Frank Macavilca <dmacavilca@syc-sistemas.com> | N3: Modulo Log 1.1 Listado Log Mejorar el performance del modulo de logs es demasiado lento Desarrollar funcioanlidad para guardar los datos del request cuadno se realizan ejemplo si se guardan leyes que valores estan siendo enviados al WAPSA para grabarse. Modificar scripts para soportar esta nueva columna que obtendrá los datos de datos enviados Crear nuevas tablas para manejar las llaves y adjuntos Modificar la UI para poder ver esta nueva columna Realizar pruebas | O3: Nuevo | P3: Requerimiento Nuevo-Area Comercial | Q3: No implica estabilización | R3: 251 | S3: =VLOOKUP(R3,Epics!A:B,2,FALSE) -> Proyecto WAPSA 2024 - 3
A4: 183 | B4: Ticket | C4: Ticket 304 - Proyecto WAPSA 2024 - 1 - Modificar Proceso Lista despacho | D4: WAPSA\Sprint - Marzo - 2026 | E4: Nuevo | J4: WAPSA web | L4: 304 | N4: Descripción: 1.1 Pesos Lista Despacho Modicar codigo en el momento que se modifiquen pesos se deben eliminar las leyes y humedades existentes. Modificar UI para consumir nuevo proceso Realizar pruebas 1.2 Humedades Lista Despacho Modicar codigo en el momento que se modifiquen pesos se deben eliminar las leyes. Modificar UI para consumir nuevo proceso Realizar pruebas Solución: | O4: Nuevo | P4: Requerimiento Nuevo-Area Comercial | Q4: No implica estabilización | R4: 251 | S4: =VLOOKUP(R4,Epics!A:B,2,FALSE) -> Proyecto WAPSA 2024 - 3
A5: 185 | B5: Ticket | C5: Ticket 306 - Proyecto WAPSA 2024 - 1 - Mantenimiento Equipos-Pesajes | D5: WAPSA\Sprint - Marzo - 2026 | E5: Nuevo | J5: WAPSA web | L5: 306 | N5: Mantenimiento de tablas 1.1 Registro de Equipos Registro de los equipos Configurar cuenta de correo 1.2 Mantenimiento de tablas Tipos de mantenimiento Tipos de averias Empresas Ubicación Registro de la programación 2.1 Registro de programación Registro de programación Registro de evidencias Envío de la notificación 2.2 Registro de mantenimiento correctivo Registro del evento Registro de las evidencias Reportes Reporte de programación Reporte de Mantenimiento Correctivo | O5: Nuevo | P5: Requerimiento Nuevo-Area Comercial | Q5: No implica estabilización | R5: 251 | S5: =VLOOKUP(R5,Epics!A:B,2,FALSE) -> Proyecto WAPSA 2024 - 3
A6: 189 | B6: Ticket | C6: Ticket 310 - Proyecto WAPSA 2024 - 1 - Arribo a Mina y a Callao con GPS | D6: WAPSA\Sprint - Marzo - 2026 | E6: Nuevo | J6: WAPSA web | L6: 310 | N6: Crear una API 1.1 Crear proceso automatico para leer datos del GPS Creacion de scripts Desarrollo del codigo con logica 1.2 Modificar el wapsa Modificar el WAPSA para soportar una lectura del gps o manual Realizar pruebas | O6: Nuevo | P6: Requerimiento Nuevo-Area Comercial | Q6: No implica estabilización | R6: 251 | S6: =VLOOKUP(R6,Epics!A:B,2,FALSE) -> Proyecto WAPSA 2024 - 3
A7: 223 | B7: Ticket | C7: Ticket 333 - Wapsa - General - Proyecto Wapsa - Rountrip con GPS | D7: WAPSA\Sprint - Marzo - 2026 | E7: Nuevo | G7: 9/4/2024 7:00:00 p. m. | J7: Wapsa Web | K7: 333 | N7: 10/04 @Cristian Pastor Artigas Reunion con el proveedor CLS Peru en la cual se concretaron los siguientes puntos: -En la aplicacion de CLS que le permite a MIna monitorear los vagones via GPS se registrar el Nro de Guia de Remision en el campo conductor, de momento manualmente lo hara el equipo de Edwin Rios MCP. -El equipo de Edwin registrara la guias desde el Jueves 11/04 hasta el dia lunes para que luego de eso SyC Sistemas podra 15/04 consultar utilizando el API. -EL dia 15/04 SyC probara haciendo consultas utilizando el API para devolver los datos filtrando por el campo conductor-Guia de remision, -La proxima reunion sera el dia 18 o 19/04 -Se concretara una reunion con Wally a posterior para ver internamnete en Wapsa cuales seran las mejoras una vez podamos consultar la informacion correctamnete desde el API -CLS indico cual es la documentacion que se debe consultar. https://sdk.wialon.com/wiki/en/sidebar/remoteapi/apiref/report/cleanup_result @Cristian Pastor Artigas Video de la reunion en los adjuntos del Ticket 15/04 Edwin Rios inidca que ya se esta cargando los Numeros de Guias desde Mina 16/04 @Cristian Pastor Artigas Se envia consulta a la Empresa del GPS para consultar sobre como obtener los ID's para obtener lueo los reportes 23/04 @Cristian Pastor Artigas CLS responde mail enviando las credenciales de acceso 29/04 @Cristian Pastor Artigas Se envia consulta a CLS porque no se puede obtener la informacion de los puntos del GPS , se solicita reunion | O7: Nuevo | P7: Requerimiento Nuevo-Area Comercial | Q7: No implica estabilización | R7: 251 | S7: =VLOOKUP(R7,Epics!A:B,2,FALSE) -> Proyecto WAPSA 2024 - 3
A8: 248 | B8: Ticket | C8: Ticket 355 Wapsa - General - Proyecto - Agregar grupos de Ensayo en Wapsa | D8: WAPSA\Sprint - Agosto - 2025 | E8: Cerrado | F8: [Ver 2.25] | G8: 2/6/2025 7:00:00 p. m. | H8: 4/8/2025 7:00:00 p. m. | I8: 7/10/2025 1:53:00 p. m. | J8: Wapsa Web | L8: 355 | M8: Cristian Pastor Artigas <cartigas@syc-sistemas.com> | N8: Luis Casas solicita: En la transmision de leyes de Cotecna e importacion: - Habilitar 4 columnas de información en el reporte de H2OyLey Callao de Wapsa; grupos (G1,G2,G3,G4) para recibir la data de Cotecna - Generar el maestro: "Grupos de análisis" para seleccionar a qué grupo pertenece cada analito. - Actualizar el reporte en Excel de H2OyLey Callao incluyendo los Grupos. - Habilitar las 4 columnas en el dashboard (HumedadesyLeyes) 28/05 @Cristian Pastor Artigas Se adjunta documento resultante de la reunion | O8: Nuevo | P8: Requerimiento Nuevo-Area Comercial | Q8: No implica estabilización | R8: 251 | S8: =VLOOKUP(R8,Epics!A:B,2,FALSE) -> Proyecto WAPSA 2024 - 3
A9: 458 | B9: Ticket | C9: Ticket 445- Wapsa - General - Pase a Produccion Wapsa Ver. 2.24 | D9: WAPSA\Sprint - Septiembre- 2025 | E9: Cerrado | F9: [Ver 2.24] | G9: 25/7/2025 5:14:00 p. m. | H9: 25/7/2025 5:14:00 p. m. | I9: 1/9/2025 6:21:00 a. m. | J9: Wapsa Web | L9: 445 | M9: Cristian Pastor Artigas <cartigas@syc-sistemas.com> | N9: Ticket de Soporte: Ticket 443 - Error al listar vagones en arribo mina en el detalle https://dev.azure.com/SycSistemas/WAPSA/_boards/board/t/WAPSA%20Team/Stories?workitem=456 Ticket 442 - Wapsa - Stock Callao - Error en calculo de TMH en listado detalle por día https://dev.azure.com/SycSistemas/WAPSA/_boards/board/t/WAPSA%20Team/Stories?workitem=450 Ticket 440- Wapsa - Mina - UBICACIÓN DE VAGONES - Corrección Listado de Vagones https://dev.azure.com/SycSistemas/WAPSA/_boards/board/t/WAPSA%20Team/Stories?workitem=445 Ticket 441- Wapsa - Mina - Stock - Revisión Lentitud Listado https://dev.azure.com/SycSistemas/WAPSA/_boards/board/t/WAPSA%20Team/Stories?workitem=446 Ticket de Proyectos: Ticket 444- Wapsa - Mina - Pesaje - Lectura del peso utilizando api de PI Server https://dev.azure.com/SycSistemas/WAPSA/_boards/board/t/WAPSA%20Team/Stories?workitem=455 Ticket 425 - Wapsa - Ruma - ENVIÓ DE DATA DE RUMA Y EJE A IMPALA https://dev.azure.com/SycSistemas/WAPSA/_boards/board/t/WAPSA%20Team/Stories?workitem=415 Ticket 429 - Wapsa- General - G. Codigo Establecimiento por cada serie https://dev.azure.com/SycSistemas/WAPSA/_boards/board/t/WAPSA%20Team/Stories?workitem=458 Para Ticket Ticket 429: Crear los codigos de establecimiento en Datos Rumas Guias de Remision Cargar 0000 en todos los clientes Impresion txt: 603 1001 Activacion Impresion por pantalla de TXT GRE PRINTX true IOAV 247 1001 Alerta de Aprobación Ejes de Ruma AAJR NULL ALER Ticket 425 Alerta de Aprobación Ejes de Ruma Destinatarios arios DER artigasc@gmail.com,melendezyessi@gmail.com,a@gmail.com DRE 0 0 1 0 NULL 2025-05-23 19:50:25.433 Chinalco dbWapsa2 2025-05-23 19:45:56.863 WAPSA 0 NULL 0 0 0 0 NULL Para ticket 444 Crear nueovo maestro Tipo Conexión Balanza Mina Datos Conexión Balanza Mina <add key="HostApiPISERVER" value="http://10.251.3.51:8081/last_value" /> <add key="UserApiPISERVER" value="user_wapsa01" /> <add key="PassApiPISERVER" value="GkXpLZ&amp;d66LNAGGPyeS5&amp;m" /> <add key="tagB1" value="PL:245WIT0064_TON_DCS" /> <add key="tagB2" value="PL:400WIT2064_TON_DCS" /> Crear ejes de descarga hasta el 30 Permisos PARA TODO: | O9: Repetitivo-en-proceso | P9: Requerimiento Nuevo-Area Comercial | Q9: No implica estabilización | R9: 252 | S9: =VLOOKUP(R9,Epics!A:B,2,FALSE) -> Pases a Producción
A10: 285 | B10: Ticket | C10: Ticket 366 - Wapsa - General - Solicitud de Pase a Producción Wapsa/WapsaUE v2.17 | D10: WAPSA\Sprint - Septiembre - 2024 | E10: Cerrado | F10: [Ver. 2.17] | G10: 14/7/2024 7:00:00 p. m. | H10: 14/7/2024 7:00:00 p. m. | I10: 26/8/2024 7:00:00 p. m. | J10: Wapsa Web | K10: 102342 | L10: 366 | M10: Cristian Pastor Artigas <cartigas@syc-sistemas.com> | N10: Pase a producción Wapsa V 2.17 Ticket 307 - Proyecto WAPSA 2024 - 2 - Mejoras en el cuadre en Wapsa https://dev.azure.com/SycSistemas/WAPSA/_boards/board/t/WAPSA%20Team/Stories/?workitem=186 Ticket 353 - Mina - Lista de Despachos-Se generó un registro duplicado al preasignar vagón por intervención del usuario https://dev.azure.com/SycSistemas/WAPSA/_boards/board/t/WAPSA%20Team/Stories/?workitem=246 Ticket 346 - Guias Electronicas - Proyecto Mejoras WAPSA - 2 - Nuevo Modulo "Emisión de Guias Impala 01" https://dev.azure.com/SycSistemas/WAPSA/_boards/board/t/WAPSA%20Team/Stories/?workitem=236 Ticket 364 - Callao - Lista de Despachos - El filtro por IE's en estado abierto no muestra las que tiene peso = 0 https://dev.azure.com/SycSistemas/WAPSA/_boards/board/t/WAPSA%20Team/Stories/?workitem=282 Ticket 347 - Guias Electronicas - Proyecto Mejoras WAPSA - 2 - GRE Impresión Guías - Hipervinculos https://dev.azure.com/SycSistemas/WAPSA/_boards/board/t/WAPSA%20Team/Stories/?workitem=237 15/07 @Cristian Pastor Artigas Creando documentos 16/07 @Cristian Pastor Artigas Se envia para firmas de AM 18/07 @Cristian Pastor Artigas Enviado a TICA | O10: Nuevo | P10: Requerimiento Nuevo-Area Comercial | Q10: No implica estabilización | R10: 252 | S10: =VLOOKUP(R10,Epics!A:B,2,FALSE) -> Pases a Producción
A11: 316 | B11: Ticket | C11: Ticket 379 - Wapsa - General - Solicitud de Pase a Producción Wapsa/WapsaUE v2.18 | D11: WAPSA\Sprint - Octubre - 2024 | E11: Cerrado | F11: [Ver. 2.18] | G11: 9/9/2024 7:00:00 p. m. | H11: 9/9/2024 7:00:00 p. m. | I11: 14/10/2024 7:00:00 p. m. | J11: Wapsa Web | K11: 120145 | L11: 379 | M11: Cristian Pastor Artigas <cartigas@syc-sistemas.com> | N11: Pase a producción Wapsa V 2.18 Ticket 302 - Guias Electronicas - Proyecto Mejoras WAPSA - 2 - Entregas Directas - Cambiar como se registra el destinatario, que no sea desde el maestro. https://dev.azure.com/SycSistemas/WAPSA/_boards/board/t/WAPSA%20Team/Stories/?workitem=178 Ticket 372 - Modulo Mina - Pesaje Manual - Mejora-Ver vagones observados https://dev.azure.com/SycSistemas/WAPSA/_boards/board/t/WAPSA%20Team/Stories/?workitem=308 Ticket 373 - Modulo Mina - Pesaje - Mejora correos supervisores https://dev.azure.com/SycSistemas/WAPSA/_boards/board/t/WAPSA%20Team/Stories/?workitem=309 Ticket 375 - Modulo Pesaje - Vagones observados - no filtra por los estados https://dev.azure.com/SycSistemas/WAPSA/_boards/board/t/WAPSA%20Team/Stories/?workitem=311 Ticket 376 - Modulo Pesaje - Registro cambio check auto/manual peso tara https://dev.azure.com/SycSistemas/WAPSA/_boards/board/t/WAPSA%20Team/Stories/?workitem=312 Ticket 383 - Callao - Volteo - Link para descargar PDF en Guias Electronicas | O11: Nuevo | P11: Requerimiento Nuevo-Area Comercial | Q11: No implica estabilización | R11: 252 | S11: =VLOOKUP(R11,Epics!A:B,2,FALSE) -> Pases a Producción
A12: 490 | B12: Ticket | C12: Ticket 458 - Wapsa - General - Pase a Produccion Wapsa v2.25 | D12: WAPSA\Sprint - Noviembre - 2025 | E12: Cerrado | F12: [Ver 2.25] | G12: 3/10/2025 8:28:00 a. m. | H12: 7/10/2025 1:48:00 p. m. | I12: 29/10/2025 4:49:00 a. m. | J12: Wapsa Web | L12: 458 | M12: Cristian Pastor Artigas <cartigas@syc-sistemas.com> | N12: Ticket 451 - Wapsa - Arribo - Ejes Ruma - No se envian los QR dentro del email https://dev.azure.com/SycSistemas/WAPSA/_boards/board/t/WAPSA%20Team/Stories?System.IterationPath=%40currentIteration&workitem=480 Ticket 450 - Wapsa - Ruma - Popup de Ejes de ve muy abajo https://dev.azure.com/SycSistemas/WAPSA/_boards/board/t/WAPSA%20Team/Stories?System.IterationPath=%40currentIteration&workitem=474 Ticket 449 - Wapsa -Monitor - Modificar Monitor Venta y crear Ventas por Evidence https://dev.azure.com/SycSistemas/WAPSA/_boards/board/t/WAPSA%20Team/Stories?System.IterationPath=%40currentIteration&workitem=474 Ticket 428 - F. Grupos de Análisis-Nuevos requerimientos (relacion Ticket 355) https://dev.azure.com/SycSistemas/WAPSA/_boards/board/t/WAPSA%20Team/Stories?System.IterationPath=%40currentIteration&workitem=418 Ticket 424 -Wapsa -General - Ajuste final https://dev.azure.com/SycSistemas/WAPSA/_boards/board/t/WAPSA%20Team/Stories?System.IterationPath=%40currentIteration&workitem=414 Ticket 315 - Wapsa - Proyecto WAPSA 2024 - 1 - Mejoras Logs https://dev.azure.com/SycSistemas/WAPSA/_boards/board/t/WAPSA%20Team/Stories?workitem=194 Ticket 453 - Envio datos WAPSA-SAP https://dev.azure.com/SycSistemas/WAPSA/_boards/board/t/WAPSA%20Team/Stories?workitem=485 | O12: Nuevo | P12: Requerimiento Nuevo-Area Comercial | Q12: Estabilización por proyecto | R12: 252 | S12: =VLOOKUP(R12,Epics!A:B,2,FALSE) -> Pases a Producción
A13: 491 | B13: Ticket | C13: Ticket 459 - Wapsa - General - Pase a Produccion Wapsa ES v4.1 | D13: WAPSA\Sprint - Noviembre - 2025 | E13: Cerrado | F13: [Ver 4.1] | G13: 7/10/2025 1:56:00 p. m. | H13: 7/10/2025 1:56:00 p. m. | I13: 29/10/2025 4:49:00 a. m. | J13: Wapsa ES | L13: 459 | M13: Cristian Pastor Artigas <cartigas@syc-sistemas.com> | N13: Ticket 403 - Wapsa ES - GRE's - Validar que existan datos de balanzas en Wapsa cuando se crea la GRE https://dev.azure.com/SycSistemas/WAPSA/_boards/board/t/WAPSA%20Team/Stories?System.IterationPath=%40currentIteration&workitem=378 Ticket 357 - WapsaES - G. Codigo Establecimiento por cada serie - Caso Impala Wapsa ES https://dev.azure.com/SycSistemas/WAPSA/_boards/board/t/WAPSA%20Team/Stories?System.IterationPath=%40currentIteration&workitem=431 Ticket 385 - Wapsa ES - General - Proyecto 2024 - Crear API para recibir/ver informacion de Grupo Ensayos (Relacion con Ticket 355) https://dev.azure.com/SycSistemas/WAPSA/_boards/board/t/WAPSA%20Team/Stories?System.IterationPath=%40currentIteration&workitem=345 Ticket 453 - Wapsa - Envio datos WAPSA-SAP https://dev.azure.com/SycSistemas/WAPSA/_boards/board/t/WAPSA%20Team/Stories?workitem=485 | O13: Nuevo | P13: Requerimiento Nuevo-Area Comercial | Q13: Estabilización de req. de Mantenimiento | R13: 252 | S13: =VLOOKUP(R13,Epics!A:B,2,FALSE) -> Pases a Producción
A14: 235 | B14: Ticket | C14: Ticket 345 - Wapsa - General - Solicitud de Pase a Producción Wapsa/WapsaUE v2.16 | D14: WAPSA\Sprint - Mayo -2024 | E14: Cerrado | F14: [Ver. 2.16] | G14: 2/5/2024 7:00:00 p. m. | H14: 19/5/2024 7:00:00 p. m. | I14: 14/5/2024 7:00:00 p. m. | J14: Wapsa Web | L14: 345 | M14: Cristian Pastor Artigas <cartigas@syc-sistemas.com> | N14: Pase a producción Wapsa V 2.16 Ticket 330 https://dev.azure.com/SycSistemas/WAPSA/_boards/board/t/WAPSA%20Team/Stories/?workitem=218 Ticket 340 https://dev.azure.com/SycSistemas/WAPSA/_workitems/edit/230 Ticket 339 https://dev.azure.com/SycSistemas/WAPSA/_workitems/edit/229 Ticket 331 https://dev.azure.com/SycSistemas/WAPSA/_workitems/edit/219 Ticket 338 https://dev.azure.com/SycSistemas/WAPSA/_workitems/edit/228 03/05 @Cristian Pastor Artigas se crea y se envía documentación para firmas de AM 03/05 @Cristian Pastor Artigas se envia pase a producción 10/05 @Cristian Pastor Artigas Se sube archivo de Manual de Usuario Actualizado 15/05 @Cristian Pastor Artigas Se suben sustentos Casos de prueba, y Alexander envia scripts a DBA para su ejecucion del pase final, a la espera de definir dia | O14: Nuevo | P14: Requerimiento Nuevo-Area Comercial | Q14: No implica estabilización | R14: 252 | S14: =VLOOKUP(R14,Epics!A:B,2,FALSE) -> Pases a Producción
A15: 245 | B15: Ticket | C15: Ticket 351 - Wapsa - General - Solicitud de Pase a Producción Wapsa/WapsaUE v2.16.1 | D15: WAPSA\Sprint - Mayo -2024 | E15: Cerrado | F15: [2.16.1] | G15: 2/5/2024 7:00:00 p. m. | H15: 28/5/2024 7:00:00 p. m. | I15: 26/5/2024 7:00:00 p. m. | J15: Wapsa Web | L15: 351 | M15: Cristian Pastor Artigas <cartigas@syc-sistemas.com> | N15: Pase a producción Wapsa V 2.16.1 Ticket 350 https://dev.azure.com/SycSistemas/WAPSA/_boards/board/t/WAPSA%20Team/Stories/?workitem=243 Ticket 352 https://dev.azure.com/SycSistemas/WAPSA/_boards/board/t/WAPSA%20Team/Stories/?workitem=244 22/05 @Cristian Pastor Artigas se crea y se envía documentación para firmas de AM 23/05 @Cristian Pastor Artigas Enviado a TICA 27/05 @Cristian Pastor Artigas WM adjunta evidencias de pruebas. Se esta a la espera de definir por parte de TICA el dia y hora de hacer los cambios en producción 29/05 @Cristian Pastor Artigas Cerrado | O15: Nuevo | P15: S&C Sistemas | Q15: Estabilización por proyecto | R15: 252 | S15: =VLOOKUP(R15,Epics!A:B,2,FALSE) -> Pases a Producción
A16: 213 | B16: Ticket | C16: Ticket 326 - Wapsa - General - Pase a Produccion Wapsa/WapsaUE v2.15 | D16: WAPSA\Sprint - Marzo 2024 | E16: Cerrado | F16: [Ver. 2.15] | G16: 13/3/2024 7:00:00 p. m. | H16: 13/3/2024 7:00:00 p. m. | I16: 21/3/2024 7:00:00 p. m. | J16: Wapsa | K16: 102342 | L16: 326 | M16: Cristian Pastor Artigas <cartigas@syc-sistemas.com> | N16: Pase a produccion Version 2.15 Ticket 303 - Proyecto WAPSA 2024 - 1 - Mejoras Embarque a Granel "Extraporturario" Lista despacho. Ticket 305 - Proyecto WAPSA 2024 - 1 - Mejoras Reporte TMH, TMS, HUMEDAD Lista despacho.  Ticket 326 - El registro de Pesaje de Mina Muestra ventana de diferencias de peso tara al momento de preasignar. Ticket 313 - Proyecto WAPSA 2024 - 1 - Aprobación Supervisor por la diferencia de peso tara en mina. Ticket 327 - Corrección error al hacer la aprobación de Pesaje Manual Módulo. Ticket 314 - Proyecto WAPSA 2024 - 1 - Alerta Lista Despacho. 14/03 Se envian documentos para firma de AM @Cristian Pastor Artigas 18/03 AM responde documentos firmados 18/03 Se envia Ticket a TICA para iniciar pase @Cristian Pastor Artigas 20/03 TICA pasa a testing 20/03 Wally revisa y envia correcciones sobre los tickets #192 y #182 20/03 TICA asigna ticket MCP #102342 | O16: Nuevo | P16: Requerimiento Nuevo-Area Comercial | Q16: No implica estabilización | R16: 252 | S16: =VLOOKUP(R16,Epics!A:B,2,FALSE) -> Pases a Producción
A17: 523 | B17: Ticket | C17: Ticket 481 - Wapsa - Pase a Produccion Wapsa v2.28 y WapsaES Ver.4.7 | D17: WAPSA\Sprint - Marzo - 2026 | E17: En Proceso firmas | G17: 20/2/2026 10:19:00 a. m. | L17: 481 | M17: Cristian Pastor Artigas <cartigas@syc-sistemas.com> | N17: Ticket 471 - Wapsa - SAP Envio de datos https://dev.azure.com/SycSistemas/WAPSA/_boards/board/t/WAPSA%20Team/Stories?workitem=507 | O17: Nuevo | P17: S&C Sistemas | Q17: No implica estabilización | R17: 252 | S17: =VLOOKUP(R17,Epics!A:B,2,FALSE) -> Pases a Producción
A18: 410 | B18: Ticket | C18: Ticket 420 - Wapsa - General - Pase a Produccion Wapsa v2.21 Mantenimiento Feb-2025 | D18: WAPSA\Sprint - Marzo - 2025 | E18: Cerrado | F18: [Ver. 2.21] | G18: 16/2/2025 7:00:00 p. m. | H18: 27/2/2025 7:00:00 p. m. | I18: 12/3/2025 7:00:00 p. m. | J18: Wapsa Web | L18: 420 | M18: Cristian Pastor Artigas <cartigas@syc-sistemas.com> | N18: Pase a producción Wapsa V 2.21: Ticket 415 - Wapsa - Callao - Inspeccion - No lista los vagones observados en estado pendiente https://dev.azure.com/SycSistemas/WAPSA/_boards/board/t/WAPSA%20Team/Stories/?workitem=398 Ticket 404- Wapsa - Mina- Despacho - Correo de Dif Peso Tara del Supervisor debe indicar la palabra Supervisor en el asunto https://dev.azure.com/SycSistemas/WAPSA/_boards/board/t/WAPSA%20Team/Stories/?workitem=380 Ticket 414 - Wapsa - Mina - Despacho - Error al intentar al preasignar despacho (Bloqueo de tablas) https://dev.azure.com/SycSistemas/WAPSA/_boards/board/t/WAPSA%20Team/Stories/?workitem=397 Ticket 412 - Wapsa - Mina - Cambiar orden de detalle de convoy para que se muestre por fecha de inspeccion https://dev.azure.com/SycSistemas/WAPSA/_boards/board/t/WAPSA%20Team/Stories/?workitem=391 Ticket 413 - Wapsa - Mina - Agregar columna en la vista y excel que se muestre el precinto de salida Callao (Precinto Cotecna) https://dev.azure.com/SycSistemas/WAPSA/_boards/board/t/WAPSA%20Team/Stories/?workitem=392 | O18: Nuevo | P18: Requerimiento Nuevo-Area Comercial | Q18: No implica estabilización | R18: 252 | S18: =VLOOKUP(R18,Epics!A:B,2,FALSE) -> Pases a Producción
A19: 434 | B19: Ticket | C19: Ticket 434 - Wapsa - General - Pase a Produccion v2.22 - Proyectos Parte 1 | D19: WAPSA\Sprint - Junio - 2025 | E19: Cerrado | F19: [Ver. 2.22] | G19: 24/4/2025 7:00:00 p. m. | H19: 27/4/2025 7:00:00 p. m. | I19: 2/6/2025 7:00:00 p. m. | J19: Wapsa Web | L19: 434 | M19: Cristian Pastor Artigas <cartigas@syc-sistemas.com> | N19: Pase a producción Wapsa V 2.22: Ticket 432- Wapsa - Mina - Despacho - Solicitar 3 adjuntos como minimo al subir evidencias de peso tara manual por evento https://dev.azure.com/SycSistemas/WAPSA/_boards/board/t/WAPSA%20Team/Stories?workitem=432 Ticket 423 - Wapsa - Mina - Pesaje - Modulo Mina - Filtros- Quitar Preautorizados https://dev.azure.com/SycSistemas/WAPSA/_boards/board/t/WAPSA%20Team/Stories?workitem=413 Ticket 422 - Wapsa - Mina - Pesaje - Modulo Mina Pesaje Manual (tara y bruto) supervisor por evento https://dev.azure.com/SycSistemas/WAPSA/_boards/board/t/WAPSA%20Team/Stories?workitem=180 | O19: Nuevo | P19: Requerimiento Nuevo-Area Comercial | Q19: No implica estabilización | R19: 252 | S19: =VLOOKUP(R19,Epics!A:B,2,FALSE) -> Pases a Producción
A20: 441 | B20: Ticket | C20: Ticket 437 - Wapsa - General - Pase a Produccion v2.23 - Nuevo Tipo de GRE "Otros" | D20: WAPSA\Sprint - Junio - 2025 | E20: Cerrado | F20: [Ver. 2.23] | G20: 11/6/2025 8:44:00 a. m. | H20: 11/6/2025 8:44:00 a. m. | I20: 24/6/2025 10:18:00 a. m. | J20: Wapsa Web | L20: 437 | M20: Cristian Pastor Artigas <cartigas@syc-sistemas.com> | N20: Pase a producción Wapsa V 2.23: Ticket 436 - Implementar nuevo caso GRE "Otros" https://dev.azure.com/SycSistemas/WAPSA/_workitems/edit/440 | O20: Nuevo | P20: Requerimiento Nuevo-Area Comercial | Q20: No implica estabilización | R20: 252 | S20: =VLOOKUP(R20,Epics!A:B,2,FALSE) -> Pases a Producción
A21: 442 | B21: Ticket | C21: Ticket 438 - WapsaES - General - Pase a Produccion v4.0 - Nuevo Tipo de GRE "Otros" | D21: WAPSA\Sprint - Junio - 2025 | E21: Cerrado | F21: [Ver 4.0] | G21: 11/6/2025 8:44:00 a. m. | H21: 11/6/2025 8:44:00 a. m. | I21: 19/6/2025 7:00:00 p. m. | J21: Wapsa Web | L21: 437 | M21: Cristian Pastor Artigas <cartigas@syc-sistemas.com> | N21: Pase a producción Wapsa V 2.23: Ticket 436 - Implementar nuevo caso GRE "Otros" https://dev.azure.com/SycSistemas/WAPSA/_workitems/edit/440 | O21: Nuevo | P21: Requerimiento Nuevo-Area Comercial | Q21: No implica estabilización | R21: 252 | S21: =VLOOKUP(R21,Epics!A:B,2,FALSE) -> Pases a Producción
